Workbook

Sheet Final lineup table
A1: Artist Name | B1: Time and place | C1: Description | D1: Genre
A2: &FRIENDS | B2: HIDEOUT STAGE - Thu 02:00-04:00 | C2: From San Diego dreams to Dubai nights, &friends turns global culture into pure dance floor magic. When Black Coffee and Diplo support your sound and Sofi Tukker wants your remixes, you know it's more than just music - it's movement. This worldwide party starter caught Coachella's ear and got 20 million streams by bringing cultures together on the dance floor. No passport needed. | D2: Global Bass / House / World
A3: ¥ØU$UK€ ¥UK1MAT$U | B3: BOOHA STAGE - Wed 00:00-02:00 | C3: This is where the vampires will headbang. After fighting brain cancer, Yousuke Yukimatsu reinvented himself as Japan's most fearless genre-bender. Shirtless and drenched in sweat, his sets are raw, emotional, and unpredictable—mixing gabber, trap, techno, and soul into sonic chaos that feels like life itself. This is more than a show; it's a testament to resilience. 🇯🇵 | D3: #N/A
A4: 30 CENTURY MAN | B4: BACKYARD STAGE - Fri 21:15-22:15 | C4: The enigmatic producer crafting tomorrow's sound today. 30 CENTURY MAN operates in the space between experimental and dancefloor-ready, creating futuristic compositions that feel both alien and familiar. His rare live appearances are events in themselves. | D4: #N/A
A5: ABASC | B5: PING PONG STAGE - Wed 22:30-00:00 | C5: Local talent ready to deliver underground electronic energy. Get ready for hypnotic beats and driving rhythms. | D5: #N/A
A6: AFTERMATH | B6: HIDEOUT STAGE - Sun 20:00-21:30 | C6: Rooted in Romania's rich musical heritage, AFTERMATH channels Afro house's fresh energy. Born to move souls and fill dancefloors, they've opened for Shimza, Jamiie, and Awen—sharing stages and making crowds lose themselves to the rhythm. | D6: Afro House
A7: AKOS | B7: HIDEOUT STAGE - Fri 20:00-22:00 | C7: Akos fell in love with electronic sounds in 2005. He views music as energy, love, and inspiration. His style focuses on deep house, house, and techno—moving crowds with soulful, driving grooves. | D7: Deep House / House / Techno
A8: ALDARIS | B8: THE BEACH STAGE - Thu 18:00-20:00 | C8: Legend says he's still searching for the perfect groove—record by record, wax story by wax story. Wherever his journey ends, Aldaris has plenty of vinyl adventures to share. Join him. | D8: Vinyl Explorer / Deep Grooves
A9: ALEX SUPER BEATS | B9: MAIN STAGE - Sun 22:30-00:00 | C9: From Cluj-Napoca to the world, Alex Super Beats (formerly DJ Shiver) has been a driving force in Romania's electronic music scene. With a career spanning over a decade, he's shared stages with global icons and launched his own imprint to push boundaries in electronic music. Expect nothing less than an electrifying journey when he takes over the Castle stage. 🔥 | D9: #N/A
A10: ALI | B10: BACKYARD STAGE - Sat 00:05-01:05 | C10: Ever heard Arabic lyrics over Indonesian funk? Ali's cooking up something wild in Jakarta - '70s rock riffs meet Middle Eastern soul, all wrapped in Southeast Asian groove. Three guys turning centuries of cultural fusion into fresh dance floor heat. | D10: Indonesian Funk / Arabic Rock
A11: ÂME | B11: BOOHA STAGE - Thu 02:00-05:00 | C11: This is electronic music's front line. 20 years ago, Âme decided club music needed more soul and started pushing the boundaries ever since. Today, whether it's Frank's live playing or Kristian's surgical mixing, Âme don't just read dancefloors - they redesign them. Get ready for a legendary performance⚡️ | D11: #N/A
A12: ANAÏS B2B HOAX + PVC | B12: HANGAR STAGE - Sat 03:00-04:00 | C12: Fresh out the gate in Bristol, Anaïs already has Glastonbury, Boomtown, and Rampage eating from her palm. Her secret weapon? Raw jungle energy meets surgical precision behind the decks. Catch her before she outgrows those underground bunkers for festival main stages. // When Hoax drops a tune, even the underground veterans stop and listen. Piano skills meet bass addiction in this Bristol lab rat's productions. Pure dance floor science. | D12: #N/A
A13: ANDI MOISESCU | B13: PING PONG STAGE - Fri 22:30-00:00 | C13: Description not available | D13: #N/A
A14: ANDI MOISESCU | B14: PING PONG STAGE - Fri 22:30-00:00 | C14: From TV screens to festival stages, Romania's beloved entertainer brings his charismatic energy to the decks. ANDI MOISESCU traded hosting duties for house music, proving that good vibes translate across all mediums. When one of Romania's most recognizable faces gets behind the decks, magic happens. | D14: #N/A
A15: ANDRA ANDRIUCĂ | B15: BACKYARD STAGE - Sun 15:00-16:00 | C15: From Iași to Electric Castle, Andra Andriucă writes songs that feel like heart-to-hearts with your best friend. Backed by her band, she blends indie vibes with pop-rock energy for tracks that hit you right in the feels. Honest music for messy lives—don't miss her set! 🎸 | D15: Pop / Folk
A16: ANFISA LETYAGO | B16: BOOHA STAGE - Fri 02:30-04:30 | C16: Anfisa Letyago's journey is as extraordinary as her sets. With Carl Cox as a fan, her hypnotic techno commands your attention without begging for it. When she's in the booth, you can't help but just surrender to the groove. ⚡️ | D16: Techno
A17: ARAPU | B17: STABLES STAGE - Sat 07:30-11:00 | C17: Arapu, a certified treasure in Bucharest's underground, has produced records since 2011 and brings seductive playfulness to his straightforward, bass-driven sets. His discography blends drones, field recordings, and bass rumble, amplifying good mood across clubs and releases on his Liniar label. | D17: House / Techno / Experimental
A18: ARTEMAS | B18: MAIN STAGE - Fri 19:30-20:30 | C18: Oxford's finest sad boy with a knack for turning emotions into bangers. The guy who makes heartbreak sound cool, blending alternative pop, dark wave, and R&B. With Gold and Platinum hits like "If U Think I'm Pretty" and "I Like the Way You Kiss Me," Artemas crafts moody soundscapes that hit you right in the feels. | D18: Alt-Pop / Dark-Pop
A19: Artist Name | B19: Stage & Time | C19: Artist Description | D19: #N/A
A20: Artist Name | B20: Stage & Time | C20: Artist Description | D20: #N/A
A21: ATTIC | B21: THE BEACH STAGE - Thu 15:00-16:00 | C21: Say you don’t know much about | D21: #N/A
A22: ATTIC | B22: THE BEACH STAGE - Thu 15:00-16:00 | C22: Local selector digging deep for the perfect groove. Expect house, disco, and electronic gems that move the soul. | D22: #N/A
A23: BAD NERVES | B23: HANGAR STAGE - Thu 19:40-20:40 | C23: Essex boys making punk rock dangerous again. Think Ramones-meet-Buzzcocks in a 21st century speed blender. Bad Nerves pack more hooks in two minutes than most bands manage in a whole album. Bad Nerves are what happens when punk's original fire meets modern production. Come lose your voice screaming along. ⚡️ | D23: Garage Punk / Power Pop
A24: BAKAYAN | B24: HIDEOUT STAGE - Sat 22:00-00:00 | C24: Guitar kid turned electronic wizard, Bákayan brings something different to Berlin's scene. Mixing his Southeast Asian roots with raw emotion, he makes dance music that hits differently. Part melody, part feeling, pure dance floor magic. | D24: #N/A
A25: BENJA | B25: HIDEOUT STAGE - Thu 04:00-06:00 | C25: The producer who turns tango into techno. Benja's tracks are like sonic postcards from a future where South America rules the dancefloor. Expect swirling synths, tribal rhythms, and enough emotion to make even the toughest ravers shed a tear. Don't forget your passport. ✈️ | D25: Electronic
A26: BENZ | B26: HIDEOUT STAGE - Fri 16:00-18:00 | C26: Benz is a Tunisian DJ drawing from African and Arab heritage—rich rhythms and percussions transformed into energetic, soulful afrohouse sets that bridge past and present, creating immersive dancefloor experiences. | D26: Afrohouse
A27: BIANCA OANCE | B27: THE BEACH STAGE - Sat 18:00-20:00 | C27: Romanian artist bringing fresh electronic energy. Expect house, pop, and dance sounds that connect with the crowd. | D27: #N/A
A28: BICEP | B28: HANGAR STAGE - Sun 23:45-01:15 | C28: From Belfast bedroom DJs to electronic music royalty, Bicep flex hard. Masters of turning dance music into pure emotion, they've got a black belt in making crowds lose their minds. Get ready to feel something real 💪 | D28: #N/A
A29: BILA | B29: STABLES STAGE - Sat 23:00-01:00 | C29: A discreet presence in electronic music, Bilǎ brings a well-balanced technical mixing approach. His productions are a nexus of classic and new sounds, creating refined, danceable experiences. | D29: #N/A
A30: BLANILLA B2B MISSILE | B30: THE BEACH STAGE - Sat 02:00-04:00 | C30: Titus Carole, the "electronica droid," has traversed genres since 2004. With versatile mixing skills and an eclectic sound selection—ranging from 4/4 beats to broken beats—he crafts good mood music that swings between mellow grooves and high-energy DJ sets. | D30: #N/A
A31: BOEBECK | B31: BACKYARD STAGE - Sat 17:30-18:20 | C31: Boebeck is a female-led new wave indie band from Hungary that's been turning heads across Europe. Their upcoming EP, Evil Under the Sun (2025), promises more of their signature blend of dreamy rock harmonies and poetic lyricism. Whether you're a fan of indie nostalgia or cutting-edge sounds, Boebeck is here to steal your heart at Electric Castle. 🌟 | D31: Indie Pop
A32: BOGDAN MALAELE | B32: PING PONG STAGE - Sat 16:00-17:00 | C32: Comedian, gamer, father, lover—and in his own words, the best DJ in the EU—Bogdan Malaele brings humor and heartfelt vibes to every performance. | D32: Comedy / DJ
A33: BON ENTENDEUR | B33: BOOHA STAGE - Sat 00:30-02:30 | C33: Two music obsessives dropping vintage voice samples over fresh beats, turning 70s gems into modern dance floor gold. 70 million streams can't be wrong. Merging classic French voices with cutting-edge production, this duo takes packed halls on a journey between decades. | D33: French Samples / Nu-Disco
A34: BOSQUITO | B34: MAIN STAGE - Sat 19:30-20:30 | C34: 25 years of turning Romanian rock into pure fire. From gypsy punk to symphonic ballads, Bosquito blend Balkan spirit with rock'n'roll heart. This anniversary show? Pure history in the making 🔥 | D34: Rock / Balkan / Gypsy Punk
A35: BRÓDY & DR.PANDA | B35: THE BEACH STAGE - Fri 01:30-03:30 | C35: Romanian duo bringing genre-blending electronic sounds. Expect house, techno, and experimental beats that surprise and delight. | D35: #N/A
A36: BRUTALISMUS 3000 | B36: HANGAR STAGE - Sat 23:30-00:30 | C36: Berlin's noisiest love story - where gabber meets punk, hardstyle meets industrial, and chaos meets genius. The soundtrack to a dystopian warehouse rave you never want to leave. He builds sonic weapons, she screams in multiple languages. Together, they're reinventing rave culture for a generation that needs it more than ever. ⚡️ | D36: Hardcore / Techno
A37: BULLY | B37: THE BEACH STAGE - Fri 03:30-05:30 | C37: Since 2000, Bully has curated genre-blending journeys—from funk grooves and house to obscure hip-hop and world music. Having played virtually every major venue in Romania and shared stages with legends like Qbert and Freestylers, his vinyl and tape collecting fuels masterful, storytelling sets that celebrate rhythm and melody. | D37: Big Beat / Breakbeat / Hip-Hop / World Music
A38: CALINACHO | B38: HANGAR STAGE - Thu 01:00-01:30 | C38: Calinacho is redefining Romanian trap with his genre-blending sound and heartfelt lyrics. With tracks like "Seara Mea" and "Lipsa Ta" from his acclaimed album Ai Grijă, he's established himself as a leading voice in Romanian R&B. Whether collaborating with big names or dropping solo hits, Calinacho brings authenticity to every performance. At Electric Castle, expect an intimate yet electrifying set from this rising star. | D38: Pop / Trap
A39: CALLY | B39: STABLES STAGE - Sun 14:00-17:00 | C39: Hailing from Craiova, Romania, caLLy (real name Dragos Gabriel Dumitru) is a forward-thinking DJ and producer whose refined sound has earned him a respected place in the global underground scene. Known for his deep, hypnotic grooves and precise minimal aesthetic, caLLy brings a unique identity to both his productions and DJ sets. His music has been released on labels such as only300, Fear of Flying, Brouqade, Rora, Fizical, Neostrictly, Soulsity, Inwave, and The Rabbit Hole. Featured on influential compilations like Cocoon Green & Blue (mixed by Tobi Neumann) and Cocoon Heroes (mixed by Adam Beyer & Dorian Paic), caLLy continues to evolve, delivering timeless sets and productions that resonate deeply on the dancefloor. | D39: Minimal / Techno
A40: CALYX | B40: BOOHA STAGE - Sun 19:00-20:00 (Hosted by GQ) | C40: Half of the legendary Calyx & TeeBee duo, Calyx brings decades of technical precision to the decks. His solo sets showcase the darker, more technical side of drum & bass—surgical beats that hit harder than a freight train. | D40: Drum & Bass
...

Sheet Sheet3
A1: Artist Name | B1: Time and place | C1: Description | D1: Genre
A2: &FRIENDS | B2: HIDEOUT STAGE - Thu 02:00-04:00 | C2: From San Diego dreams to Dubai nights, &friends turns global culture into pure dance floor magic. When Black Coffee and Diplo support your sound and Sofi Tukker wants your remixes, you know it's more than just music - it's movement. This worldwide party starter caught Coachella's ear and got 20 million streams by bringing cultures together on the dance floor. No passport needed. | D2: =VLOOKUP(A2, Sheet2!A:B, 2, FALSE) -> Global Bass / House / World
A3: ¥ØU$UK€ ¥UK1MAT$U | B3: BOOHA STAGE - Wed 00:00-02:00 | C3: This is where the vampires will headbang. After fighting brain cancer, Yousuke Yukimatsu reinvented himself as Japan's most fearless genre-bender. Shirtless and drenched in sweat, his sets are raw, emotional, and unpredictable—mixing gabber, trap, techno, and soul into sonic chaos that feels like life itself. This is more than a show; it's a testament to resilience. 🇯🇵 | D3: =VLOOKUP(A3, Sheet2!A:B, 2, FALSE) -> #N/A
A4: 30 CENTURY MAN | B4: BACKYARD STAGE - Fri 21:15-22:15 | C4: The enigmatic producer crafting tomorrow's sound today. 30 CENTURY MAN operates in the space between experimental and dancefloor-ready, creating futuristic compositions that feel both alien and familiar. His rare live appearances are events in themselves. | D4: =VLOOKUP(A4, Sheet2!A:B, 2, FALSE) -> #N/A
A5: ABASC | B5: PING PONG STAGE - Wed 22:30-00:00 | C5: Local talent ready to deliver underground electronic energy. Get ready for hypnotic beats and driving rhythms. | D5: =VLOOKUP(A5, Sheet2!A:B, 2, FALSE) -> #N/A
A6: AFTERMATH | B6: HIDEOUT STAGE - Sun 20:00-21:30 | C6: Rooted in Romania's rich musical heritage, AFTERMATH channels Afro house's fresh energy. Born to move souls and fill dancefloors, they've opened for Shimza, Jamiie, and Awen—sharing stages and making crowds lose themselves to the rhythm. | D6: =VLOOKUP(A6, Sheet2!A:B, 2, FALSE) -> Afro House
A7: AKOS | B7: HIDEOUT STAGE - Fri 20:00-22:00 | C7: Akos fell in love with electronic sounds in 2005. He views music as energy, love, and inspiration. His style focuses on deep house, house, and techno—moving crowds with soulful, driving grooves. | D7: =VLOOKUP(A7, Sheet2!A:B, 2, FALSE) -> Deep House / House / Techno
A8: ALDARIS | B8: THE BEACH STAGE - Thu 18:00-20:00 | C8: Legend says he's still searching for the perfect groove—record by record, wax story by wax story. Wherever his journey ends, Aldaris has plenty of vinyl adventures to share. Join him. | D8: =VLOOKUP(A8, Sheet2!A:B, 2, FALSE) -> Vinyl Explorer / Deep Grooves
A9: ALEX SUPER BEATS | B9: MAIN STAGE - Sun 22:30-00:00 | C9: From Cluj-Napoca to the world, Alex Super Beats (formerly DJ Shiver) has been a driving force in Romania's electronic music scene. With a career spanning over a decade, he's shared stages with global icons and launched his own imprint to push boundaries in electronic music. Expect nothing less than an electrifying journey when he takes over the Castle stage. 🔥 | D9: =VLOOKUP(A9, Sheet2!A:B, 2, FALSE) -> #N/A
A10: ALI | B10: BACKYARD STAGE - Sat 00:05-01:05 | C10: Ever heard Arabic lyrics over Indonesian funk? Ali's cooking up something wild in Jakarta - '70s rock riffs meet Middle Eastern soul, all wrapped in Southeast Asian groove. Three guys turning centuries of cultural fusion into fresh dance floor heat. | D10: =VLOOKUP(A10, Sheet2!A:B, 2, FALSE) -> Indonesian Funk / Arabic Rock
A11: ÂME | B11: BOOHA STAGE - Thu 02:00-05:00 | C11: This is electronic music's front line. 20 years ago, Âme decided club music needed more soul and started pushing the boundaries ever since. Today, whether it's Frank's live playing or Kristian's surgical mixing, Âme don't just read dancefloors - they redesign them. Get ready for a legendary performance⚡️ | D11: =VLOOKUP(A11, Sheet2!A:B, 2, FALSE) -> #N/A
A12: ANAÏS B2B HOAX + PVC | B12: HANGAR STAGE - Sat 03:00-04:00 | C12: Fresh out the gate in Bristol, Anaïs already has Glastonbury, Boomtown, and Rampage eating from her palm. Her secret weapon? Raw jungle energy meets surgical precision behind the decks. Catch her before she outgrows those underground bunkers for festival main stages. // When Hoax drops a tune, even the underground veterans stop and listen. Piano skills meet bass addiction in this Bristol lab rat's productions. Pure dance floor science. | D12: =VLOOKUP(A12, Sheet2!A:B, 2, FALSE) -> #N/A
A13: ANDI MOISESCU | B13: PING PONG STAGE - Fri 22:30-00:00 | C13: Description not available | D13: =VLOOKUP(A13, Sheet2!A:B, 2, FALSE) -> #N/A
... A251: ZO | B251: BOOHA STAGE - Sat 14:00-16:00 | C251: Cluj-based promoter-turned-DJ ZO has pushed the local bass scene for seven years, booking acts like Loefah and Commodo. His dancefloor-oriented sets span hip-hop, dub, UK garage, and DnB, always delivering top-notch selection. | D251: =VLOOKUP(A251, Sheet2!A:B, 2, FALSE) -> Hip-Hop / Dub / UK Garage / Drum & Bass

Sheet Sheet2
A1: Artist | B1: Genre(s) | C1: Schedule | D1: Description
A2: &Friends | B2: Global Bass / House / World | C2: Thursday, July 17 @ HIDEOUT STAGE by #unlockwonder | D2: From San Diego dreams to Dubai nights, &friends turns global culture into pure dance floor magic. When Black Coffee and Diplo support your sound and Sofi Tukker wants your remixes, you know it's more than just music - it's movement. This worldwide party starter caught Coachella's ear and got 20 million streams by bringing cultures together on the dance floor. No passport needed.
A3: ¥ØU | B3: Experimental / Techno | C3: Wednesday, July 16 @ BOOHA STAGE by glo | D3: Hey, I'm not up to date with too much about them, check the app to see what they're all about.
A4: AFTERMATH | B4: Afro House | C4: Thursday, July 17 @ HIDEOUT STAGE by #unlockwonder | D4: Rooted in Romania’s rich musical heritage, AFTERMATH channels Afro house’s fresh energy... they’ve opened for Shimza, Jamiie, and Awen—sharing stages and making crowds lose themselves to the rhythm.
A5: Akos | B5: Deep House / House / Techno | C5: Friday, July 18 @ HIDEOUT STAGE by #unlockwonder | D5: Akos fell in love with electronic sounds in 2005. He views music as energy, love, and inspiration. His style focuses on deep house, house, and techno—moving crowds with soulful, driving grooves.
A6: ALDARIS | B6: Vinyl Explorer / Deep Grooves | C6: Thursday, July 17 @ THE BEACH STAGE | D6: Legend says he’s still searching for the perfect groove—record by record, wax story by wax story. Wherever his journey ends, Aldaris has plenty of vinyl adventures to share. Join him.
A7: ALI | B7: Indonesian Funk / Arabic Rock | C7: Saturday, July 19 @ BACKYARD STAGE by MobilaDalin | D7: Ever heard Arabic lyrics over Indonesian funk? Ali's cooking up something wild in Jakarta - '70s rock riffs meet Middle Eastern soul, all wrapped in Southeast Asian groove. Three guys turning centuries of cultural fusion into fresh dance floor heat.
A8: Âme DJ Set | B8: Deep House / Techno | C8: Thursday, July 17 @ BOOHA STAGE by glo | D8: Electronic music's front line: 20 years of breathing soul into club music. Whether Frank’s live or Kristian’s surgical mixing, Âme redesign dancefloors. Get ready for legend status. ⚡️
A9: Anaïs | B9: Jungle / Breakbeat / Bass | C9: Saturday, July 19 @ HANGAR STAGE by Banca Transilvania | D9: Fresh from Bristol: Anaïs’s raw jungle energy and surgical precision launched her to Glastonbury, Boomtown, and Rampage. Catch her before she outgrows the underground.
A10: ANDRA ANDRIUCĂ | B10: Pop / Folk | C10: Sunday, July 20 @ BACKYARD STAGE by MobilaDalin | D10: Hey, I'm not up to date with too much about her, check the app to see what she's all about.
A11: Andrei Ciubuc | B11: Minimal / Techno | C11: Schedule and stage not available. | D11: Andrei Ciubuc is one of the artists belonging to the new wave of Romanian underground minimal producers and DJs. Passionate since childhood, he developed a special relationship with music—starting analog on violin before expanding to guitar and bass guitar. Assisted by his experience as a sound engineer, he created his own label “Draganenii,” imprinting a unique, easily recognizable style of versatility at every opportunity. Andrei is part of the trio “Backstage Boys” alongside Dan Andrei and Kozo, as well as the collaborative duos “VRAC” with Vlad Radu and “A_R” with Rhadoo.
A12: Andrei Lacatuș (Shurubel) | B12: Funky House | C12: Sunday, July 20 @ HIDEOUT STAGE by #unlockwonder | D12: I was a radio DJ for 10 years and a resident DJ for 5 years in a wild Bucharest student club—throwing house, dubstep, DnB, and heavy tracks from 10 PM to 7 AM. Now I gently place smooth funky house rhythms into the minds and bodies of the crowd. Don’t shy away!
... A235: ZO | B235: Hip-Hop / Dub / UK Garage / Drum & Bass | C235: Saturday, July 19 @ BOOHA STAGE by glo | D235: Cluj-based promoter-turned-DJ ZO has pushed the local bass scene for seven years, booking acts like Loefah and Commodo. His dancefloor-oriented sets span hip-hop, dub, UK garage, and DnB, always delivering top-notch selection.
